<?xml version="1.0"?>
<robot name="robot_kustom">

    <!-- Sasis -->
    <link name="sasis">
        <visual>
            <geometry>
                <box size="0.25 0.15 0.1"/>
            </geometry>
            <material name="abu_abu"/>
        </visual>
    </link>

    <!-- Roda kiri depan -->
    <link name="roda_kiri_depan">
        <visual>
            <geometry>
                <cylinder radius="0.05" length="0.02"/>
            </geometry>
            <material name="hitam"/>
        </visual>
    </link>

    <!-- Roda kanan depan -->
    <link name="roda_kanan_depan">
        <visual>
            <geometry>
                <cylinder radius="0.05" length="0.02"/>
            </geometry>
            <material name="hitam"/>
        </visual>
    </link>

    <!-- Sambungan -->
    <joint name="sasis_ke_roda_kiri" type="continuous">
        <parent link="sasis"/>
        <child link="roda_kiri_depan"/>
        <origin xyz="0.12 0.08 0"/>
    </joint>

    <joint name="sasis_ke_roda_kanan" type="continuous">
        <parent link="sasis"/>
        <child link="roda_kanan_depan"/>
        <origin xyz="0.12 -0.08 0"/>
    </joint>

</robot>

